<?xml version='1.0'?>

<robot name="myrobot" xmlns:xacro="http://www.ros.org/wiki/xacro">

  <xacro:property name="cameraSize" value="0.3"/>
  <xacro:property name="cameraMass" value="0.1"/>

  <xacro:include filename="$(find mybot_description)/urdf/mybot.gazebo" />
  <xacro:include filename="$(find mybot_description)/urdf/materials.xacro" />
  <xacro:include filename="$(find mybot_description)/urdf/macros.xacro" />


  <link name="chassis">
    <inertial>
      <mass value="4300.0"/>
      <origin rpy="0  0  0" xyz="0  0  0"/>
      <inertia ixx="83700.5" ixy="0.0" ixz="0.0" iyy="752000.8" iyz="0.0" izz="808300.3"/>
    </inertial>

    <collision name="collision">
      <origin rpy="0  0  0" xyz="0  0  1"/>
<!--      <geometry>-->
<!--        <mesh filename="package://jsk_mbzirc_common/gazebo_model/models/truck/meshes/truck.dae" scale=".0025 .0015 .0015"/>-->
<!--      </geometry>-->
    </collision>

    <visual name="visual">
      <origin rpy="0  0  0" xyz="0  0  1"/>
      <geometry>
        <mesh filename="package://mybot_description/meshes/truck.dae" scale=".0025 .0015 .0015"/>
      </geometry>
      <material name="color"> 
        <color rgba="0 0 0 1"/>
      </material>
    </visual>

    <collision name='caster_front_collision'>
      <origin xyz="0 0 0.5" rpy=" 0 0 0"/>
      <geometry>
        <sphere radius="0.5"/>
      </geometry>
      <surface>
        <friction>
          <ode>
            <mu>0</mu>
            <mu2>0</mu2>
            <slip1>0</slip1>
            <slip2>0</slip2>
          </ode>
        </friction>
      </surface>
    </collision>

    <visual name='caster_front_visual'>
      <origin xyz="0 0 0.5" rpy=" 0 0 0"/>
      <geometry>
        <sphere radius="0.5"/>
      </geometry>
    </visual>

  </link>

  <link name="cabinet">
    <inertial>
      <mass value="1000.0"/>
      <origin rpy="0  0  0" xyz="0  0  0"/>
      <inertia ixx="837.5" ixy="0.0" ixz="0.0" iyy="7520.8" iyz="0.0" izz="8083.3"/>
    </inertial>

    <collision name="collision">
      <origin rpy="0  0  0" xyz="-1.5  0  -3"/>
      <geometry>
        <box size="2.375 2.495 3.353"/>
      </geometry>
    </collision>

    <visual name="visual">
      <origin rpy="0  0  0" xyz="-1.5  0  -3"/>
      <geometry>
        <box size="2.375 2.495 3.353"/>
      </geometry>
    </visual>
  </link>


<link name="front_left_wheel">
    <inertial>
      <mass value="100.0"/>
      <origin rpy="0  0  0" xyz="0  0  0"/>
      <inertia ixx="5" ixy="0.0" ixz="0.0" iyy="5" iyz="0.0" izz="5"/>
    </inertial>
    <collision name="collision">
      <origin rpy="0  0  0" xyz="0  0  0"/>
      <geometry>
        <cylinder length="0.3" radius="0.882"/>
      </geometry>
    </collision>
    <visual name="visual">
      <origin rpy="0  0  0" xyz="0  0  0"/>
      <geometry>
        <cylinder length="0.3" radius="0.882"/>
      </geometry>
      <material name="color">
        <color rgba="0 0 0  1"/>
      </material>
    </visual>
  </link>
 
  <link name="front_right_wheel">
    <inertial>
      <mass value="100.0"/>
      <origin rpy="0  0  0" xyz="0  0  0"/>
       <inertia ixx="5" ixy="0.0" ixz="0.0" iyy="5" iyz="0.0" izz="5"/>
    </inertial>
    <collision name="collision">
      <origin rpy="0  0  0" xyz="0  0  0"/>
      <geometry>
        <cylinder length="0.3" radius="0.882"/>
      </geometry>
    </collision>
    <visual name="visual">
      <origin rpy="0  0  0" xyz="0  0  0"/>
      <geometry>
        <cylinder length="0.3" radius="0.882"/>
      </geometry>
      <material name="color">
        <color rgba="0 0 0 1"/>
      </material>    </visual>
  </link>

  <link name="rear_left_wheel">
    <inertial>
      <mass value="100.0"/>
      <origin rpy="0  0  0" xyz="0  0  0"/>
       <inertia ixx="5" ixy="0.0" ixz="0.0" iyy="5" iyz="0.0" izz="5"/>
    </inertial>
    <collision name="collision">
      <origin rpy="0  0  0" xyz="0  0  0"/>
      <geometry>
        <cylinder length="0.3" radius="0.882"/>
      </geometry>
    </collision>
    <visual name="visual">
      <origin rpy="0  0  0" xyz="0  0  0"/>
      <geometry>
        <cylinder length="0.3" radius="0.882"/>
      </geometry>
    </visual>
  </link>

  <link name="rear_right_wheel">
    <inertial>
      <mass value="100.0"/>
      <origin rpy="0  0  0" xyz="0  0  0"/>
       <inertia ixx="5" ixy="0.0" ixz="0.0" iyy="5" iyz="0.0" izz="5"/>
    </inertial>
    <collision name="collision">
      <origin rpy="0  0  0" xyz="0  0  0"/>
      <geometry>
        <cylinder length="0.3" radius="0.882"/>
      </geometry>
    </collision>
    <visual name="visual">
      <origin rpy="0  0  0" xyz="0  0  0"/>
      <geometry>
        <cylinder length="0.3" radius="0.882"/>
      </geometry>
    </visual>
  </link>




  <link name="camera">
    <collision>
      <origin xyz="3.2 0 0.83499" rpy="0 0 0"/>
      <geometry>
        <box size="${cameraSize} ${cameraSize} ${cameraSize}"/>
      </geometry>
    </collision>

    <visual>
      <origin xyz="0 0 0.83499" rpy="0 0 0"/>
      <geometry>
        <box size="${cameraSize} ${cameraSize} ${cameraSize}"/>
      </geometry>
      <material name="green"/>
    </visual>

    <inertial>
      <mass value="${cameraMass}" />
      <origin xyz="3.2 0 0.83499" rpy="0 0 0"/>
      <box_inertia m="${cameraMass}" x="${cameraSize}" y="${cameraSize}" z="${cameraSize}" />
      <inertia ixx="1e-6" ixy="0" ixz="0" iyy="1e-6" iyz="0" izz="1e-6" />
    </inertial>
  </link>

  <joint name="camera_joint" type="fixed">
    <axis xyz="0 1 0" />
    <origin xyz="3.2 0 0.83499" rpy="0 0 0"/>
    <parent link="chassis"/>
    <child link="camera"/>
  </joint>

  <link name="hokuyo">
    <collision name="front_lidar__collision-base">
      <origin rpy="0  0  0" xyz="0      0     -0.0145"/>
      <geometry>
        <box size="0.5 0.05 0.041"/>
      </geometry>
    </collision>
    <collision name="front_lidar__collision-top">
      <origin rpy="0  0  0" xyz="0     0      0.0205"/>
      <geometry>
        <cylinder length="0.029" radius="0.021"/>
      </geometry>
    </collision>

    <visual>
      <origin xyz="0 0 0" rpy="0 0 0"/>
      <geometry>
        <mesh filename="package://mybot_description/meshes/hokuyo.dae"/>
      </geometry>
    </visual>

    <inertial>
      <mass value="1e-5" />
      <origin xyz="0 0 0" rpy="0 0 0"/>
      <inertia ixx="1e-6" ixy="0" ixz="0" iyy="1e-6" iyz="0" izz="1e-6" />
    </inertial>
  </link>


  <joint name="main_cabinet_hinge" type="fixed">
    <parent link="chassis"/>
    <child link="cabinet"/>
    <origin rpy="0  0  0" xyz="3    0    5.75"/>
    <axis xyz="0  1  0"/>
    <limit effort="0.0" lower="0.0" upper="0.0" velocity="0.0"/>
  </joint>



 <joint name="front_left_wheel_hinge" type="continuous">
    <parent link="chassis"/>
    <child link="front_left_wheel"/>
    <origin rpy="0      1.5707  1.5707" xyz="1      1.2475  0.882"/>
    <axis xyz="0   0   1.00000000e+00"/>
    <limit effort="100000" velocity="10000"/>
    <joint_properties damping="10" friction="10"/>
  </joint>

  <joint name="front_right_wheel_hinge" type="continuous">
    <parent link="chassis"/>
    <child link="front_right_wheel"/>
    <origin rpy="0      1.5707  1.5707" xyz="1     -1.2475  0.882"/>
    <axis xyz="0   0   1.00000000e+00"/>
    <dynamics damping="0.01"/>
    <limit effort="100000" lower="0" upper="0" velocity="10000"/>
    <joint_properties damping="10" friction="10"/>
  </joint>
  <joint name="rear_left_wheel_hinge" type="continuous">
    <parent link="chassis"/>
    <child link="rear_left_wheel"/>
    <origin rpy="0      1.5707  1.5707" xyz="-2      1.2475  0.882"/>
    <axis xyz="9.00000000e-05   9.00000000e-05   1.00000000e+00"/>
    <limit effort="10000" lower="0" upper="0" velocity="1000"/>
  </joint>

  <joint name="rear_right_wheel_hinge" type="continuous">
    <parent link="chassis"/>
    <child link="rear_right_wheel"/>
    <origin rpy="0      1.5707  1.5707" xyz="-2     -1.2475  0.882"/>
    <dynamics damping="0.01"/>
    <axis xyz="9.00000000e-05   9.00000000e-05   1.00000000e+00"/>
    <limit effort="10000" lower="0" upper="0" velocity="1000"/>
  </joint>


  <joint name="hokuyo_joint" type="fixed">
    <axis xyz="0 0 1" />
    <origin xyz="3.2 0 1.03499" rpy="0 0 0"/>
    <parent link="chassis"/>
    <child link="hokuyo"/>
  </joint>



</robot>

