<sdf version='1.6'>
  <world name='default'>
    <light name='sun' type='directional'>
      <cast_shadows>1</cast_shadows>
      <pose frame=''>0 0 10 0 -0 0</pose>
      <diffuse>0.8 0.8 0.8 1</diffuse>
      <specular>0.2 0.2 0.2 1</specular>
      <attenuation>
        <range>1000</range>
        <constant>0.9</constant>
        <linear>0.01</linear>
        <quadratic>0.001</quadratic>
      </attenuation>
      <direction>-0.5 0.1 -0.9</direction>
    </light>
    <gravity>0 0 -9.8</gravity>
    <magnetic_field>6e-06 2.3e-05 -4.2e-05</magnetic_field>
    <atmosphere type='adiabatic'/>
    <physics name='default_physics' default='0' type='ode'>
      <max_step_size>0.001</max_step_size>
      <real_time_factor>1</real_time_factor>
      <real_time_update_rate>1000</real_time_update_rate>
    </physics>
    <scene>
      <ambient>0.4 0.4 0.4 1</ambient>
      <background>0.7 0.7 0.7 1</background>
      <shadows>1</shadows>
    </scene>
    <wind/>
    <spherical_coordinates>
      <surface_model>EARTH_WGS84</surface_model>
      <latitude_deg>0</latitude_deg>
      <longitude_deg>0</longitude_deg>
      <elevation>0</elevation>
      <heading_deg>0</heading_deg>
    </spherical_coordinates>
    <model name='mcity'>
      <static>1</static>
      <link name='link'>
        <collision name='collision'>
          <geometry>
            <mesh>
              <scale>0.254 0.254 0.254</scale>
              <uri>model://mcity/meshes/mcity.obj</uri>
            </mesh>
          </geometry>
          <max_contacts>10</max_contacts>
          <surface>
            <contact>
              <ode/>
            </contact>
            <bounce/>
            <friction>
              <torsional>
                <ode/>
              </torsional>
              <ode/>
            </friction>
          </surface>
        </collision>
        <visual name='visual'>
          <geometry>
            <mesh>
              <scale>0.254 0.254 0.254</scale>
              <uri>model://mcity/meshes/mcity.obj</uri>
            </mesh>
          </geometry>
        </visual>
        <self_collide>0</self_collide>
        <enable_wind>0</enable_wind>
        <kinematic>0</kinematic>
      </link>
      <pose frame=''>8.54594 -9.02429 0 0 -0 0</pose>
    </model>
    <model name='container-multi-stack'>
      <static>1</static>
      <link name='chassis'>
        <pose frame=''>0 0 0 0 -0 0</pose>
        <collision name='collision'>
          <geometry>
            <mesh>
              <uri>model://container-multi-stack/container-multi-stack.dae</uri>
            </mesh>
          </geometry>
          <max_contacts>10</max_contacts>
          <surface>
            <contact>
              <ode/>
            </contact>
            <bounce/>
            <friction>
              <torsional>
                <ode/>
              </torsional>
              <ode/>
            </friction>
          </surface>
        </collision>
        <visual name='visual'>
          <geometry>
            <mesh>
              <uri>model://container-multi-stack/container-multi-stack.dae</uri>
            </mesh>
          </geometry>
        </visual>
        <self_collide>0</self_collide>
        <enable_wind>0</enable_wind>
        <kinematic>0</kinematic>
      </link>
      <pose frame=''>-9.27311 11.2299 0 0 -0 0</pose>
    </model>
    <model name='container-multi-stack_0'>
      <static>1</static>
      <link name='chassis'>
        <pose frame=''>0 0 0 0 -0 0</pose>
        <collision name='collision'>
          <geometry>
            <mesh>
              <uri>model://container-multi-stack/container-multi-stack.dae</uri>
            </mesh>
          </geometry>
          <max_contacts>10</max_contacts>
          <surface>
            <contact>
              <ode/>
            </contact>
            <bounce/>
            <friction>
              <torsional>
                <ode/>
              </torsional>
              <ode/>
            </friction>
          </surface>
        </collision>
        <visual name='visual'>
          <geometry>
            <mesh>
              <uri>model://container-multi-stack/container-multi-stack.dae</uri>
            </mesh>
          </geometry>
        </visual>
        <self_collide>0</self_collide>
        <enable_wind>0</enable_wind>
        <kinematic>0</kinematic>
      </link>
      <pose frame=''>-8.9943 32.1935 0 0 -0 0</pose>
    </model>
    <state world_name='default'>
      <sim_time>1016 175000000</sim_time>
      <real_time>72 394636519</real_time>
      <wall_time>1610606577 340552708</wall_time>
      <iterations>72253</iterations>
      <model name='car_beetle'>
        <pose frame=''>85.4603 -71.8572 0 0 -0 3.14</pose>
        <scale>1 1 1</scale>
        <link name='link'>
          <pose frame=''>85.4603 -71.8572 0 0 -0 3.14</pose>
          <velocity>0 0 0 0 -0 0</velocity>
          <acceleration>0 0 0 0 -0 0</acceleration>
          <wrench>0 0 0 0 -0 0</wrench>
        </link>
      </model>
      <model name='car_beetle_0'>
        <pose frame=''>85.3281 -87.1237 0 0 -0 3.14</pose>
        <scale>1 1 1</scale>
        <link name='link'>
          <pose frame=''>85.3281 -87.1237 0 0 -0 3.14</pose>
          <velocity>0 0 0 0 -0 0</velocity>
          <acceleration>0 0 0 0 -0 0</acceleration>
          <wrench>0 0 0 0 -0 0</wrench>
        </link>
      </model>
      <model name='car_beetle_1'>
        <pose frame=''>86.1049 -101.352 0 0 -0 3.14</pose>
        <scale>1 1 1</scale>
        <link name='link'>
          <pose frame=''>86.1049 -101.352 0 0 -0 3.14</pose>
          <velocity>0 0 0 0 -0 0</velocity>
          <acceleration>0 0 0 0 -0 0</acceleration>
          <wrench>0 0 0 0 -0 0</wrench>
        </link>
      </model>
      <model name='car_beetle_2'>
        <pose frame=''>85.6531 -113.872 0 0 -0 3.14</pose>
        <scale>1 1 1</scale>
        <link name='link'>
          <pose frame=''>85.6531 -113.872 0 0 -0 3.14</pose>
          <velocity>0 0 0 0 -0 0</velocity>
          <acceleration>0 0 0 0 -0 0</acceleration>
          <wrench>0 0 0 0 -0 0</wrench>
        </link>
      </model>
      <model name='container-multi-stack'>
        <pose frame=''>-9.27311 11.2299 0 0 -0 0</pose>
        <scale>1 1 1</scale>
        <link name='chassis'>
          <pose frame=''>-9.27311 11.2299 0 0 -0 0</pose>
          <velocity>0 0 0 0 -0 0</velocity>
          <acceleration>0 0 0 0 -0 0</acceleration>
          <wrench>0 0 0 0 -0 0</wrench>
        </link>
      </model>
      <model name='container-multi-stack_0'>
        <pose frame=''>-8.9943 32.1935 0 0 -0 0</pose>
        <scale>1 1 1</scale>
        <link name='chassis'>
          <pose frame=''>-8.9943 32.1935 0 0 -0 0</pose>
          <velocity>0 0 0 0 -0 0</velocity>
          <acceleration>0 0 0 0 -0 0</acceleration>
          <wrench>0 0 0 0 -0 0</wrench>
        </link>
      </model>
      <model name='mcity'>
        <pose frame=''>171.984 -24.108 0 0 -0 0</pose>
        <scale>1 1 1</scale>
        <link name='link'>
          <pose frame=''>171.984 -24.108 0 0 -0 0</pose>
          <velocity>0 0 0 0 -0 0</velocity>
          <acceleration>0 0 0 0 -0 0</acceleration>
          <wrench>0 0 0 0 -0 0</wrench>
        </link>
      </model>
      <model name='mybot'>
        <pose frame=''>94.6367 -57.9143 6e-06 -2e-06 7e-06 -1.50662</pose>
        <scale>1 1 1</scale>
        <link name='chassis'>
          <pose frame=''>94.6367 -57.9143 6e-06 -2e-06 7e-06 -1.50662</pose>
          <velocity>0.002974 -0.000149 0.000767 1.3e-05 0.00212 0.000643</velocity>
          <acceleration>0.081984 0.060257 2.08973 0.101868 -0.734822 -3.03843</acceleration>
          <wrench>434.524 319.368 11075.8 0 -0 0</wrench>
        </link>
        <link name='front_left_wheel'>
          <pose frame=''>95.9457 -58.8323 0.882005 1.5707 -0.947034 1.63495</pose>
          <velocity>0.005638 0.00079 -0.004191 0.000612 -0.007279 0.000441</velocity>
          <acceleration>-1.07788 -2.74406 -7.3019 1.00586 -0.785754 0.256395</acceleration>
          <wrench>-107.788 -274.406 -730.189 0 -0 0</wrench>
        </link>
        <link name='front_right_wheel'>
          <pose frame=''>93.4559 -58.9923 0.882011 1.57072 0.50565 1.63484</pose>
          <velocity>0.005828 -0.000902 0.006094 0.001092 0.006613 0.000598</velocity>
          <acceleration>-1.72667 2.98039 11.773 0.609759 1.16654 -2.58884</acceleration>
          <wrench>-172.667 298.039 1177.3 0 -0 0</wrench>
        </link>
        <link name='rear_left_wheel'>
          <pose frame=''>95.7533 -55.8384 0.882013 1.57088 0.031521 1.63488</pose>
          <velocity>0.003363 0.000566 -0.000669 -0.004209 0.00101 0.000662</velocity>
          <acceleration>5.19828 -2.5244 -1.16166 2.94096 0.019207 0.803265</acceleration>
          <wrench>519.828 -252.44 -116.167 0 -0 0</wrench>
        </link>
        <link name='rear_right_wheel'>
          <pose frame=''>93.2635 -55.9985 0.88202 -1.57054 1.0797 -1.50643</pose>
          <velocity>0.003297 -0.001076 0.002274 0.001328 0.003744 0.000662</velocity>
          <acceleration>4.7117 3.3257 5.95869 0.096491 0.076562 -2.34414</acceleration>
          <wrench>471.17 332.57 595.869 0 -0 0</wrench>
        </link>
      </model>
      <light name='sun'>
        <pose frame=''>0 0 10 0 -0 0</pose>
      </light>
    </state>
    <gui fullscreen='0'>
      <camera name='user_camera'>
        <pose frame=''>92.7324 20.4422 51.1 0 0.689797 -2.05589</pose>
        <view_controller>orbit</view_controller>
        <projection_type>perspective</projection_type>
      </camera>
    </gui>
    <model name='mybot'>
      <link name='chassis'>
        <pose frame=''>0 0 0 0 -0 0</pose>
        <inertial>
          <pose frame=''>0.566148 0 1.08492 0 -0 0</pose>
          <mass>5300.1</mass>
          <inertia>
            <ixx>28499.3</ixx>
            <ixy>0</ixy>
            <ixz>-13995.6</ixz>
            <iyy>49171.2</iyy>
            <iyz>0</iyz>
            <izz>23471.9</izz>
          </inertia>
        </inertial>
        <collision name='chassis_fixed_joint_lump__camera_collision'>
          <pose frame=''>6.4 0 1.66998 0 -0 0</pose>
          <geometry>
            <box>
              <size>0.3 0.3 0.3</size>
            </box>
          </geometry>
          <surface>
            <contact>
              <ode/>
            </contact>
            <friction>
              <ode/>
              <torsional>
                <ode/>
              </torsional>
            </friction>
            <bounce/>
          </surface>
          <max_contacts>10</max_contacts>
        </collision>
        <collision name='chassis_fixed_joint_lump__front_lidar__collision-base_collision_1'>
          <pose frame=''>3.2 0 1.02049 0 -0 0</pose>
          <geometry>
            <box>
              <size>0.5 0.05 0.041</size>
            </box>
          </geometry>
          <max_contacts>10</max_contacts>
          <surface>
            <contact>
              <ode/>
            </contact>
            <bounce/>
            <friction>
              <torsional>
                <ode/>
              </torsional>
              <ode/>
            </friction>
          </surface>
        </collision>
        <collision name='chassis_fixed_joint_lump__front_lidar__collision-top_collision_2'>
          <pose frame=''>3.2 0 1.05549 0 -0 0</pose>
          <geometry>
            <cylinder>
              <length>0.029</length>
              <radius>0.021</radius>
            </cylinder>
          </geometry>
          <max_contacts>10</max_contacts>
          <surface>
            <contact>
              <ode/>
            </contact>
            <bounce/>
            <friction>
              <torsional>
                <ode/>
              </torsional>
              <ode/>
            </friction>
          </surface>
        </collision>
        <collision name='chassis_fixed_joint_lump__collision_collision_3'>
          <pose frame=''>1.5 0 2.75 0 -0 0</pose>
          <geometry>
            <box>
              <size>2.375 2.495 3.353</size>
            </box>
          </geometry>
          <max_contacts>10</max_contacts>
          <surface>
            <contact>
              <ode/>
            </contact>
            <bounce/>
            <friction>
              <torsional>
                <ode/>
              </torsional>
              <ode/>
            </friction>
          </surface>
        </collision>
        <visual name='chassis_fixed_joint_lump__visual_visual'>
          <pose frame=''>0 0 1 0 -0 0</pose>
          <geometry>
            <mesh>
              <scale>0.0025 0.0015 0.0015</scale>
              <uri>/home/zhou/mybot_ws/src/mybot_description/meshes/truck.dae</uri>
            </mesh>
          </geometry>
        </visual>
        <visual name='chassis_fixed_joint_lump__caster_front_visual_visual_1'>
          <pose frame=''>0 0 0.5 0 -0 0</pose>
          <geometry>
            <sphere>
              <radius>0.5</radius>
            </sphere>
          </geometry>
        </visual>
        <visual name='chassis_fixed_joint_lump__camera_visual_2'>
          <pose frame=''>3.2 0 1.66998 0 -0 0</pose>
          <geometry>
            <box>
              <size>0.3 0.3 0.3</size>
            </box>
          </geometry>
          <material>
            <script>
              <name>Gazebo/Green</name>
              <uri>file://media/materials/scripts/gazebo.material</uri>
            </script>
          </material>
        </visual>
        <visual name='chassis_fixed_joint_lump__hokuyo_visual_3'>
          <pose frame=''>3.2 0 1.03499 0 -0 0</pose>
          <geometry>
            <mesh>
              <scale>1 1 1</scale>
              <uri>/home/zhou/mybot_ws/src/mybot_description/meshes/hokuyo.dae</uri>
            </mesh>
          </geometry>
          <material>
            <script>
              <uri>__default__</uri>
              <name>__default__</name>
            </script>
          </material>
        </visual>
        <visual name='chassis_fixed_joint_lump__visual_visual_4'>
          <pose frame=''>1.5 0 2.75 0 -0 0</pose>
          <geometry>
            <box>
              <size>2.375 2.495 3.353</size>
            </box>
          </geometry>
        </visual>
        <velocity_decay/>
        <velocity_decay/>
        <sensor name='camera1' type='camera'>
          <update_rate>30</update_rate>
          <camera name='head'>
            <horizontal_fov>1.39626</horizontal_fov>
            <image>
              <width>800</width>
              <height>800</height>
              <format>R8G8B8</format>
            </image>
            <clip>
              <near>0.02</near>
              <far>300</far>
            </clip>
          </camera>
          <plugin name='camera_controller' filename='libgazebo_ros_camera.so'>
            <alwaysOn>1</alwaysOn>
            <updateRate>0.0</updateRate>
            <cameraName>mybot/camera1</cameraName>
            <imageTopicName>image_raw</imageTopicName>
            <cameraInfoTopicName>camera_info</cameraInfoTopicName>
            <frameName>camera</frameName>
            <hackBaseline>0.07</hackBaseline>
            <distortionK1>0.0</distortionK1>
            <distortionK2>0.0</distortionK2>
            <distortionK3>0.0</distortionK3>
            <distortionT1>0.0</distortionT1>
            <distortionT2>0.0</distortionT2>
            <robotNamespace>/</robotNamespace>
          </plugin>
          <pose frame=''>3.2 0 0.83499 0 -0 0</pose>
        </sensor>
        <gravity>1</gravity>
        <velocity_decay/>
        <sensor name='head_hokuyo_sensor' type='gpu_ray'>
          <visualize>1</visualize>
          <update_rate>40</update_rate>
          <ray>
            <scan>
              <horizontal>
                <samples>720</samples>
                <resolution>1</resolution>
                <min_angle>-1.5708</min_angle>
                <max_angle>1.5708</max_angle>
              </horizontal>
            </scan>
            <range>
              <min>0.1</min>
              <max>30</max>
              <resolution>0.01</resolution>
            </range>
            <noise>
              <type>gaussian</type>
              <mean>0</mean>
              <stddev>0.01</stddev>
            </noise>
          </ray>
          <plugin name='gazebo_ros_head_hokuyo_controller' filename='libgazebo_ros_gpu_laser.so'>
            <topicName>/mybot/laser/scan</topicName>
            <frameName>hokuyo</frameName>
            <robotNamespace>/</robotNamespace>
          </plugin>
          <pose frame=''>3.2 0 1.03499 0 -0 0</pose>
        </sensor>
        <self_collide>0</self_collide>
        <enable_wind>0</enable_wind>
        <kinematic>0</kinematic>
      </link>
      <link name='front_left_wheel'>
        <pose frame=''>1 1.2475 0.882 -0 1.5707 1.5707</pose>
        <inertial>
          <pose frame=''>0 0 0 0 -0 0</pose>
          <mass>100</mass>
          <inertia>
            <ixx>5</ixx>
            <ixy>0</ixy>
            <ixz>0</ixz>
            <iyy>5</iyy>
            <iyz>0</iyz>
            <izz>5</izz>
          </inertia>
        </inertial>
        <collision name='front_left_wheel_fixed_joint_lump__collision_collision'>
          <pose frame=''>0 0 0 0 -0 0</pose>
          <geometry>
            <cylinder>
              <length>0.3</length>
              <radius>0.882</radius>
            </cylinder>
          </geometry>
          <max_contacts>10</max_contacts>
          <surface>
            <contact>
              <ode/>
            </contact>
            <bounce/>
            <friction>
              <torsional>
                <ode/>
              </torsional>
              <ode/>
            </friction>
          </surface>
        </collision>
        <visual name='front_left_wheel_fixed_joint_lump__visual_visual'>
          <pose frame=''>0 0 0 0 -0 0</pose>
          <geometry>
            <cylinder>
              <length>0.3</length>
              <radius>0.882</radius>
            </cylinder>
          </geometry>
        </visual>
        <gravity>1</gravity>
        <velocity_decay/>
        <self_collide>0</self_collide>
        <enable_wind>0</enable_wind>
        <kinematic>0</kinematic>
      </link>
      <joint name='front_left_wheel_hinge' type='revolute'>
        <child>front_left_wheel</child>
        <parent>chassis</parent>
        <axis>
          <xyz>9.6e-05 1 9.6e-05</xyz>
          <limit>
            <lower>-1e+16</lower>
            <upper>1e+16</upper>
          </limit>
          <dynamics>
            <spring_reference>0</spring_reference>
            <spring_stiffness>0</spring_stiffness>
          </dynamics>
          <use_parent_model_frame>1</use_parent_model_frame>
        </axis>
      </joint>
      <link name='front_right_wheel'>
        <pose frame=''>1 -1.2475 0.882 -0 1.5707 1.5707</pose>
        <inertial>
          <pose frame=''>0 0 0 0 -0 0</pose>
          <mass>100</mass>
          <inertia>
            <ixx>5</ixx>
            <ixy>0</ixy>
            <ixz>0</ixz>
            <iyy>5</iyy>
            <iyz>0</iyz>
            <izz>5</izz>
          </inertia>
        </inertial>
        <collision name='front_right_wheel_fixed_joint_lump__collision_collision'>
          <pose frame=''>0 0 0 0 -0 0</pose>
          <geometry>
            <cylinder>
              <length>0.3</length>
              <radius>0.882</radius>
            </cylinder>
          </geometry>
          <max_contacts>10</max_contacts>
          <surface>
            <contact>
              <ode/>
            </contact>
            <bounce/>
            <friction>
              <torsional>
                <ode/>
              </torsional>
              <ode/>
            </friction>
          </surface>
        </collision>
        <visual name='front_right_wheel_fixed_joint_lump__visual_visual'>
          <pose frame=''>0 0 0 0 -0 0</pose>
          <geometry>
            <cylinder>
              <length>0.3</length>
              <radius>0.882</radius>
            </cylinder>
          </geometry>
        </visual>
        <gravity>1</gravity>
        <velocity_decay/>
        <self_collide>0</self_collide>
        <enable_wind>0</enable_wind>
        <kinematic>0</kinematic>
      </link>
      <joint name='front_right_wheel_hinge' type='revolute'>
        <child>front_right_wheel</child>
        <parent>chassis</parent>
        <axis>
          <xyz>9.6e-05 1 9.6e-05</xyz>
          <limit>
            <lower>-1e+16</lower>
            <upper>1e+16</upper>
          </limit>
          <dynamics>
            <damping>0.01</damping>
            <friction>0</friction>
            <spring_reference>0</spring_reference>
            <spring_stiffness>0</spring_stiffness>
          </dynamics>
          <use_parent_model_frame>1</use_parent_model_frame>
        </axis>
      </joint>
      <link name='rear_left_wheel'>
        <pose frame=''>-2 1.2475 0.882 -0 1.5707 1.5707</pose>
        <inertial>
          <pose frame=''>0 0 0 0 -0 0</pose>
          <mass>100</mass>
          <inertia>
            <ixx>5</ixx>
            <ixy>0</ixy>
            <ixz>0</ixz>
            <iyy>5</iyy>
            <iyz>0</iyz>
            <izz>5</izz>
          </inertia>
        </inertial>
        <collision name='rear_left_wheel_fixed_joint_lump__collision_collision'>
          <pose frame=''>0 0 0 0 -0 0</pose>
          <geometry>
            <cylinder>
              <length>0.3</length>
              <radius>0.882</radius>
            </cylinder>
          </geometry>
          <max_contacts>10</max_contacts>
          <surface>
            <contact>
              <ode/>
            </contact>
            <bounce/>
            <friction>
              <torsional>
                <ode/>
              </torsional>
              <ode/>
            </friction>
          </surface>
        </collision>
        <visual name='rear_left_wheel_fixed_joint_lump__visual_visual'>
          <pose frame=''>0 0 0 0 -0 0</pose>
          <geometry>
            <cylinder>
              <length>0.3</length>
              <radius>0.882</radius>
            </cylinder>
          </geometry>
        </visual>
        <self_collide>0</self_collide>
        <enable_wind>0</enable_wind>
        <kinematic>0</kinematic>
      </link>
      <joint name='rear_left_wheel_hinge' type='revolute'>
        <child>rear_left_wheel</child>
        <parent>chassis</parent>
        <axis>
          <xyz>6e-06 1 6e-06</xyz>
          <limit>
            <lower>-1e+16</lower>
            <upper>1e+16</upper>
          </limit>
          <dynamics>
            <spring_reference>0</spring_reference>
            <spring_stiffness>0</spring_stiffness>
          </dynamics>
          <use_parent_model_frame>1</use_parent_model_frame>
        </axis>
      </joint>
      <link name='rear_right_wheel'>
        <pose frame=''>-2 -1.2475 0.882 -0 1.5707 1.5707</pose>
        <inertial>
          <pose frame=''>0 0 0 0 -0 0</pose>
          <mass>100</mass>
          <inertia>
            <ixx>5</ixx>
            <ixy>0</ixy>
            <ixz>0</ixz>
            <iyy>5</iyy>
            <iyz>0</iyz>
            <izz>5</izz>
          </inertia>
        </inertial>
        <collision name='rear_right_wheel_fixed_joint_lump__collision_collision'>
          <pose frame=''>0 0 0 0 -0 0</pose>
          <geometry>
            <cylinder>
              <length>0.3</length>
              <radius>0.882</radius>
            </cylinder>
          </geometry>
          <max_contacts>10</max_contacts>
          <surface>
            <contact>
              <ode/>
            </contact>
            <bounce/>
            <friction>
              <torsional>
                <ode/>
              </torsional>
              <ode/>
            </friction>
          </surface>
        </collision>
        <visual name='rear_right_wheel_fixed_joint_lump__visual_visual'>
          <pose frame=''>0 0 0 0 -0 0</pose>
          <geometry>
            <cylinder>
              <length>0.3</length>
              <radius>0.882</radius>
            </cylinder>
          </geometry>
        </visual>
        <self_collide>0</self_collide>
        <enable_wind>0</enable_wind>
        <kinematic>0</kinematic>
      </link>
      <joint name='rear_right_wheel_hinge' type='revolute'>
        <child>rear_right_wheel</child>
        <parent>chassis</parent>
        <axis>
          <xyz>6e-06 1 6e-06</xyz>
          <limit>
            <lower>-1e+16</lower>
            <upper>1e+16</upper>
          </limit>
          <dynamics>
            <damping>0.01</damping>
            <friction>0</friction>
            <spring_reference>0</spring_reference>
            <spring_stiffness>0</spring_stiffness>
          </dynamics>
          <use_parent_model_frame>1</use_parent_model_frame>
        </axis>
      </joint>
      <static>0</static>
      <plugin name='differential_drive_controller' filename='libgazebo_ros_diff_drive.so'>
        <legacyMode>0</legacyMode>
        <alwaysOn>0</alwaysOn>
        <updateRate>10</updateRate>
        <leftJoint>front_left_wheel_hinge</leftJoint>
        <rightJoint>front_right_wheel_hinge</rightJoint>
        <wheelSeparation>0.4</wheelSeparation>
        <wheelDiameter>0.2</wheelDiameter>
        <wheelTorque>45000</wheelTorque>
        <wheelAcceleration>40000.0</wheelAcceleration>
        <commandTopic>cmd_vel</commandTopic>
        <odometryTopic>odom</odometryTopic>
        <odometryFrame>odom</odometryFrame>
        <robotBaseFrame>chassis</robotBaseFrame>
        <robotNamespace>/</robotNamespace>
      </plugin>
      <pose frame=''>0 0 0 0 -0 0</pose>
    </model>
    <model name='car_beetle'>
      <pose frame=''>85.4603 -71.8572 0 0 -0 3.14</pose>
      <static>1</static>
      <link name='link'>
        <inertial>
          <mass>1</mass>
          <inertia>
            <ixx>0.083</ixx>
            <ixy>0</ixy>
            <ixz>0</ixz>
            <iyy>0.083</iyy>
            <iyz>0</iyz>
            <izz>0.083</izz>
          </inertia>
        </inertial>
        <collision name='collision'>
          <geometry>
            <box>
              <size>1 1 1</size>
            </box>
          </geometry>
          <max_contacts>10</max_contacts>
          <surface>
            <contact>
              <ode/>
            </contact>
            <bounce/>
            <friction>
              <torsional>
                <ode/>
              </torsional>
              <ode/>
            </friction>
          </surface>
        </collision>
        <visual name='visual'>
          <geometry>
            <mesh>
              <uri>model://car_beetle/meshes/beetle.dae</uri>
            </mesh>
          </geometry>
        </visual>
        <self_collide>0</self_collide>
        <enable_wind>0</enable_wind>
        <kinematic>0</kinematic>
      </link>
    </model>
    <model name='car_beetle_0'>
      <pose frame=''>85.3281 -87.1237 0 0 -0 3.14</pose>
      <static>1</static>
      <link name='link'>
        <inertial>
          <mass>1</mass>
          <inertia>
            <ixx>0.083</ixx>
            <ixy>0</ixy>
            <ixz>0</ixz>
            <iyy>0.083</iyy>
            <iyz>0</iyz>
            <izz>0.083</izz>
          </inertia>
        </inertial>
        <collision name='collision'>
          <geometry>
            <box>
              <size>1 1 1</size>
            </box>
          </geometry>
          <max_contacts>10</max_contacts>
          <surface>
            <contact>
              <ode/>
            </contact>
            <bounce/>
            <friction>
              <torsional>
                <ode/>
              </torsional>
              <ode/>
            </friction>
          </surface>
        </collision>
        <visual name='visual'>
          <geometry>
            <mesh>
              <uri>model://car_beetle/meshes/beetle.dae</uri>
            </mesh>
          </geometry>
        </visual>
        <self_collide>0</self_collide>
        <enable_wind>0</enable_wind>
        <kinematic>0</kinematic>
      </link>
    </model>
    <model name='car_beetle_1'>
      <pose frame=''>86.1049 -101.352 0 0 -0 3.14</pose>
      <static>1</static>
      <link name='link'>
        <inertial>
          <mass>1</mass>
          <inertia>
            <ixx>0.083</ixx>
            <ixy>0</ixy>
            <ixz>0</ixz>
            <iyy>0.083</iyy>
            <iyz>0</iyz>
            <izz>0.083</izz>
          </inertia>
        </inertial>
        <collision name='collision'>
          <geometry>
            <box>
              <size>1 1 1</size>
            </box>
          </geometry>
          <max_contacts>10</max_contacts>
          <surface>
            <contact>
              <ode/>
            </contact>
            <bounce/>
            <friction>
              <torsional>
                <ode/>
              </torsional>
              <ode/>
            </friction>
          </surface>
        </collision>
        <visual name='visual'>
          <geometry>
            <mesh>
              <uri>model://car_beetle/meshes/beetle.dae</uri>
            </mesh>
          </geometry>
        </visual>
        <self_collide>0</self_collide>
        <enable_wind>0</enable_wind>
        <kinematic>0</kinematic>
      </link>
    </model>
    <model name='car_beetle_2'>
      <pose frame=''>85.6531 -113.872 0 0 -0 3.14</pose>
      <static>1</static>
      <link name='link'>
        <inertial>
          <mass>1</mass>
          <inertia>
            <ixx>0.083</ixx>
            <ixy>0</ixy>
            <ixz>0</ixz>
            <iyy>0.083</iyy>
            <iyz>0</iyz>
            <izz>0.083</izz>
          </inertia>
        </inertial>
        <collision name='collision'>
          <geometry>
            <box>
              <size>1 1 1</size>
            </box>
          </geometry>
          <max_contacts>10</max_contacts>
          <surface>
            <contact>
              <ode/>
            </contact>
            <bounce/>
            <friction>
              <torsional>
                <ode/>
              </torsional>
              <ode/>
            </friction>
          </surface>
        </collision>
        <visual name='visual'>
          <geometry>
            <mesh>
              <uri>model://car_beetle/meshes/beetle.dae</uri>
            </mesh>
          </geometry>
        </visual>
        <self_collide>0</self_collide>
        <enable_wind>0</enable_wind>
        <kinematic>0</kinematic>
      </link>
    </model>
  </world>
</sdf>
